Workbook

Sheet Summary
B1: Count by status/town | C1: Boxborough | D1: Littleton | E1: Westford | F1: Carlisle | G1: Concord | H1: Sudbury | I1: Maynard | J1: Stow | K1: Total
B2: {=_xlfn._xlws.SORT(_xlfn.UNIQUE(Monuments!N2:N52))} -> Couldn't paint | C2: =COUNTIFS(Monuments!$N$2:$N$52,$B2,Monuments!C$2:C$52,"X") -> 0 | D2: =COUNTIFS(Monuments!$N$2:$N$52,$B2,Monuments!D$2:D$52,"X") -> 1 | E2: =COUNTIFS(Monuments!$N$2:$N$52,$B2,Monuments!E$2:E$52,"X") -> 0 | F2: =COUNTIFS(Monuments!$N$2:$N$52,$B2,Monuments!F$2:F$52,"X") -> 0 | G2: =COUNTIFS(Monuments!$N$2:$N$52,$B2,Monuments!G$2:G$52,"X") -> 0 | H2: =COUNTIFS(Monuments!$N$2:$N$52,$B2,Monuments!H$2:H$52,"X") -> 0 | I2: =COUNTIFS(Monuments!$N$2:$N$52,$B2,Monuments!I$2:I$52,"X") -> 0 | J2: =COUNTIFS(Monuments!$N$2:$N$52,$B2,Monuments!J$2:J$52,"X") -> 0 | K2: =COUNTIF(Monuments!N$2:N$52,B2) -> 1
B3: Documented | C3: =COUNTIFS(Monuments!$N$2:$N$52,$B3,Monuments!C$2:C$52,"X") -> 0 | D3: =COUNTIFS(Monuments!$N$2:$N$52,$B3,Monuments!D$2:D$52,"X") -> 0 | E3: =COUNTIFS(Monuments!$N$2:$N$52,$B3,Monuments!E$2:E$52,"X") -> 2 | F3: =COUNTIFS(Monuments!$N$2:$N$52,$B3,Monuments!F$2:F$52,"X") -> 1 | G3: =COUNTIFS(Monuments!$N$2:$N$52,$B3,Monuments!G$2:G$52,"X") -> 0 | H3: =COUNTIFS(Monuments!$N$2:$N$52,$B3,Monuments!H$2:H$52,"X") -> 0 | I3: =COUNTIFS(Monuments!$N$2:$N$52,$B3,Monuments!I$2:I$52,"X") -> 1 | J3: =COUNTIFS(Monuments!$N$2:$N$52,$B3,Monuments!J$2:J$52,"X") -> 0 | K3: =COUNTIF(Monuments!N$2:N$52,B3) -> 4
B4: Found | C4: =COUNTIFS(Monuments!$N$2:$N$52,$B4,Monuments!C$2:C$52,"X") -> 0 | D4: =COUNTIFS(Monuments!$N$2:$N$52,$B4,Monuments!D$2:D$52,"X") -> 1 | E4: =COUNTIFS(Monuments!$N$2:$N$52,$B4,Monuments!E$2:E$52,"X") -> 0 | F4: =COUNTIFS(Monuments!$N$2:$N$52,$B4,Monuments!F$2:F$52,"X") -> 0 | G4: =COUNTIFS(Monuments!$N$2:$N$52,$B4,Monuments!G$2:G$52,"X") -> 1 | H4: =COUNTIFS(Monuments!$N$2:$N$52,$B4,Monuments!H$2:H$52,"X") -> 0 | I4: =COUNTIFS(Monuments!$N$2:$N$52,$B4,Monuments!I$2:I$52,"X") -> 1 | J4: =COUNTIFS(Monuments!$N$2:$N$52,$B4,Monuments!J$2:J$52,"X") -> 0 | K4: =COUNTIF(Monuments!N$2:N$52,B4) -> 3
B5: Not Found | C5: =COUNTIFS(Monuments!$N$2:$N$52,$B5,Monuments!C$2:C$52,"X") -> 3 | D5: =COUNTIFS(Monuments!$N$2:$N$52,$B5,Monuments!D$2:D$52,"X") -> 6 | E5: =COUNTIFS(Monuments!$N$2:$N$52,$B5,Monuments!E$2:E$52,"X") -> 4 | F5: =COUNTIFS(Monuments!$N$2:$N$52,$B5,Monuments!F$2:F$52,"X") -> 0 | G5: =COUNTIFS(Monuments!$N$2:$N$52,$B5,Monuments!G$2:G$52,"X") -> 3 | H5: =COUNTIFS(Monuments!$N$2:$N$52,$B5,Monuments!H$2:H$52,"X") -> 0 | I5: =COUNTIFS(Monuments!$N$2:$N$52,$B5,Monuments!I$2:I$52,"X") -> 0 | J5: =COUNTIFS(Monuments!$N$2:$N$52,$B5,Monuments!J$2:J$52,"X") -> 0 | K5: =COUNTIF(Monuments!N$2:N$52,B5) -> 15
B6: Painted | C6: =COUNTIFS(Monuments!$N$2:$N$52,$B6,Monuments!C$2:C$52,"X") -> 4 | D6: =COUNTIFS(Monuments!$N$2:$N$52,$B6,Monuments!D$2:D$52,"X") -> 5 | E6: =COUNTIFS(Monuments!$N$2:$N$52,$B6,Monuments!E$2:E$52,"X") -> 2 | F6: =COUNTIFS(Monuments!$N$2:$N$52,$B6,Monuments!F$2:F$52,"X") -> 5 | G6: =COUNTIFS(Monuments!$N$2:$N$52,$B6,Monuments!G$2:G$52,"X") -> 8 | H6: =COUNTIFS(Monuments!$N$2:$N$52,$B6,Monuments!H$2:H$52,"X") -> 1 | I6: =COUNTIFS(Monuments!$N$2:$N$52,$B6,Monuments!I$2:I$52,"X") -> 5 | J6: =COUNTIFS(Monuments!$N$2:$N$52,$B6,Monuments!J$2:J$52,"X") -> 5 | K6: =COUNTIF(Monuments!N$2:N$52,B6) -> 28
B8: All status | C8: =SUM(C2:C7) -> 7 | D8: =SUM(D2:D7) -> 13 | E8: =SUM(E2:E7) -> 8 | F8: =SUM(F2:F7) -> 6 | G8: =SUM(G2:G7) -> 12 | H8: =SUM(H2:H7) -> 1 | I8: =SUM(I2:I7) -> 7 | J8: =SUM(J2:J7) -> 5 | K8: =SUM(C8:J8) -> 59
A11: Monuments | B11: The main sheet with data for each monument or potential monument
A12: Contacts | B12: Dates and names of participants and observers
A13: KML CornersFromState | B13: An export from state GIS of the Acton corners in KML format. That's in WGS84 (EPSG 4326), the datum we used.

Sheet Monuments
A1: Name | B1: Type | C1: Boxborough | D1: Littleton | E1: Westford | F1: Carlisle | G1: Concord | H1: Sudbury | I1: Maynard | J1: Stow | K1: Nearest Acton street name | L1: Nearest other town street name | M1: Nearby landmark | N1: Status | O1: Date of visit | P1: Notes on location | Q1: From 1904 description | R1: Notes on Monument | S1: Coordinate Source | T1: Latitude | U1: D | V1: M | W1: S | X1: Longitude | Y1: D- | Z1: M- | AA1: S- | AB1: OpenStreetMap link | AC1: Tie-break number | AD1: Order | AE1: Possible Next Steps
A2: ="Acton"&IF(C2="X","/Boxborough","")&IF(F2="X","/Carlisle","")&IF(G2="X","/Concord","")&IF(D2="X","/Littleton","")&IF(I2="X","/Maynard","")&IF(J2="X","/Stow","")&IF(H2="X","/Sudbury","")&IF(E2="X","/Westford","")&IF(ISBLANK(AC2),""," "&AC2) &IF(OR(B2="Street Crossing",B2="Witness")," "&K2,"") -> Acton/Boxborough Central Street | B2: Street Crossing | C2: X | K2: Central Street | L2: Central Street | N2: Painted | O2: 45916 | P2: a few feet from boundary sign, on west side of road | Q2: roadstones on the westerly side of the road between West Acton and the village of New Town | S2: GIS iPad | T2: 42.495950 | U2: =IF(ISBLANK(T2),"",ABS(TRUNC(T2))) -> 42 | V2: =IF(ISBLANK(T2),"",TRUNC(ABS(T2-TRUNC(T2))*60)) -> 29 | W2: =IF(ISBLANK(T2),"",(T2 -(U2+V2/60))*60*60) -> 45.42 | X2: -71.476441 | Y2: =ABS(TRUNC(X2)) -> 71 | Z2: =TRUNC(ABS(X2-TRUNC(X2))*60) -> 28 | AA2: =(ABS(X2) -(Y2+Z2/60))*60*60 -> 35.1876 | AB2: =IF(ISBLANK(T2),"","https://openstreetmap.org/?mlat="&T2&"&mlon="&X2&"#map=16/"&T2&"/"&X2) -> https://openstreetmap.org/?mlat=42.495950&mlon=-71.476441#map=16/42.495950/-71.476441 | AD2: 38
A3: ="Acton"&IF(C3="X","/Boxborough","")&IF(F3="X","/Carlisle","")&IF(G3="X","/Concord","")&IF(D3="X","/Littleton","")&IF(I3="X","/Maynard","")&IF(J3="X","/Stow","")&IF(H3="X","/Sudbury","")&IF(E3="X","/Westford","")&IF(ISBLANK(AC3),""," "&AC3) &IF(OR(B3="Street Crossing",B3="Witness")," "&K3,"") -> Acton/Boxborough Littlefield Road | B3: Street Crossing | C3: X | K3: Littlefield Road | N3: Painted | O3: 45967 | P3: right next to mailbox south side of road | Q3: on the southerly side of Blanchard street | R3: Protected by homeowner with plantings and trellis in summer. Went back to paint in the Fall after trellis came down. | S3: GIS iPad | T3: 42.492639 | U3: =IF(ISBLANK(T3),"",ABS(TRUNC(T3))) -> 42 | V3: =IF(ISBLANK(T3),"",TRUNC(ABS(T3-TRUNC(T3))*60)) -> 29 | W3: =IF(ISBLANK(T3),"",(T3 -(U3+V3/60))*60*60) -> 33.5004 | X3: -71.478718 | Y3: =ABS(TRUNC(X3)) -> 71 | Z3: =TRUNC(ABS(X3-TRUNC(X3))*60) -> 28 | AA3: =(ABS(X3) -(Y3+Z3/60))*60*60 -> 43.3848 | AB3: =IF(ISBLANK(T3),"","https://openstreetmap.org/?mlat="&T3&"&mlon="&X3&"#map=16/"&T3&"/"&X3) -> https://openstreetmap.org/?mlat=42.492639&mlon=-71.478718#map=16/42.492639/-71.478718 | AD3: 39
A4: ="Acton"&IF(C4="X","/Boxborough","")&IF(F4="X","/Carlisle","")&IF(G4="X","/Concord","")&IF(D4="X","/Littleton","")&IF(I4="X","/Maynard","")&IF(J4="X","/Stow","")&IF(H4="X","/Sudbury","")&IF(E4="X","/Westford","")&IF(ISBLANK(AC4),""," "&AC4) &IF(OR(B4="Street Crossing",B4="Witness")," "&K4,"") -> Acton/Boxborough Mass Ave (Rte 111) | B4: Street Crossing | C4: X | K4: Mass Ave (Rte 111) | N4: Not Found | O4: 45952 | P4: Searched 10/22 near boundary sign, on both sides of the stream, with no luck. Boxborough also had it missing in 2007. | Q4: on the southerly side of Worcester turnpike | S4: map estimate | T4: 42.4783 | U4: =IF(ISBLANK(T4),"",ABS(TRUNC(T4))) -> 42 | V4: =IF(ISBLANK(T4),"",TRUNC(ABS(T4-TRUNC(T4))*60)) -> 28 | W4: =IF(ISBLANK(T4),"",(T4 -(U4+V4/60))*60*60) -> 41.88 | X4: -71.48856 | Y4: =IF(ISBLANK(X4),"",ABS(TRUNC(X4))) -> 71 | Z4: =IF(ISBLANK(X4),"",TRUNC(ABS(X4-TRUNC(X4))*60)) -> 29 | AA4: =IF(ISBLANK(X4),"",(ABS(X4) -(Y4+Z4/60))*60*60) -> 18.816 | AB4: =IF(ISBLANK(T4),"","https://openstreetmap.org/?mlat="&T4&"&mlon="&X4&"#map=16/"&T4&"/"&X4) -> https://openstreetmap.org/?mlat=42.4783&mlon=-71.48856#map=16/42.4783/-71.48856 | AD4: 40 | AE4: See if Mass DOT has records.
A5: ="Acton"&IF(C5="X","/Boxborough","")&IF(F5="X","/Carlisle","")&IF(G5="X","/Concord","")&IF(D5="X","/Littleton","")&IF(I5="X","/Maynard","")&IF(J5="X","/Stow","")&IF(H5="X","/Sudbury","")&IF(E5="X","/Westford","")&IF(ISBLANK(AC5),""," "&AC5) &IF(OR(B5="Street Crossing",B5="Witness")," "&K5,"") -> Acton/Boxborough Rte 2 | B5: Street Crossing | C5: X | K5: Rte 2 | N5: Not Found | O5: 45792 | P5: probably never placed: too close to corner | Q5: no | S5: map estimate | T5: 42.4996 | U5: =IF(ISBLANK(T5),"",ABS(TRUNC(T5))) -> 42 | V5: =IF(ISBLANK(T5),"",TRUNC(ABS(T5-TRUNC(T5))*60)) -> 29 | W5: =IF(ISBLANK(T5),"",(T5 -(U5+V5/60))*60*60) -> 58.56 | X5: -71.47389 | Y5: =IF(ISBLANK(X5),"",ABS(TRUNC(X5))) -> 71 | Z5: =IF(ISBLANK(X5),"",TRUNC(ABS(X5-TRUNC(X5))*60)) -> 28 | AA5: =IF(ISBLANK(X5),"",(ABS(X5) -(Y5+Z5/60))*60*60) -> 26.004 | AB5: =IF(ISBLANK(T5),"","https://openstreetmap.org/?mlat="&T5&"&mlon="&X5&"#map=16/"&T5&"/"&X5) -> https://openstreetmap.org/?mlat=42.4996&mlon=-71.47389#map=16/42.4996/-71.47389 | AD5: 37
A6: ="Acton"&IF(C6="X","/Boxborough","")&IF(F6="X","/Carlisle","")&IF(G6="X","/Concord","")&IF(D6="X","/Littleton","")&IF(I6="X","/Maynard","")&IF(J6="X","/Stow","")&IF(H6="X","/Sudbury","")&IF(E6="X","/Westford","")&IF(ISBLANK(AC6),""," "&AC6) &IF(OR(B6="Street Crossing",B6="Witness")," "&K6,"") -> Acton/Boxborough Summer Street | B6: Street Crossing | C6: X | K6: Summer Street | L6: Summer Rd | N6: Painted | O6: 45916 | P6: south side, near boundary sign | Q6: on the southerly side of the South Acton road. | S6: GIS iPad | T6: 42.473254 | U6: =IF(ISBLANK(T6),"",ABS(TRUNC(T6))) -> 42 | V6: =IF(ISBLANK(T6),"",TRUNC(ABS(T6-TRUNC(T6))*60)) -> 28 | W6: =IF(ISBLANK(T6),"",(T6 -(U6+V6/60))*60*60) -> 23.7144 | X6: -71.492056 | Y6: =IF(ISBLANK(X6),"",ABS(TRUNC(X6))) -> 71 | Z6: =IF(ISBLANK(X6),"",TRUNC(ABS(X6-TRUNC(X6))*60)) -> 29 | AA6: =IF(ISBLANK(X6),"",(ABS(X6) -(Y6+Z6/60))*60*60) -> 31.4016 | AB6: =IF(ISBLANK(T6),"","https://openstreetmap.org/?mlat="&T6&"&mlon="&X6&"#map=16/"&T6&"/"&X6) -> https://openstreetmap.org/?mlat=42.473254&mlon=-71.492056#map=16/42.473254/-71.492056 | AD6: 41
A7: ="Acton"&IF(C7="X","/Boxborough","")&IF(F7="X","/Carlisle","")&IF(G7="X","/Concord","")&IF(D7="X","/Littleton","")&IF(I7="X","/Maynard","")&IF(J7="X","/Stow","")&IF(H7="X","/Sudbury","")&IF(E7="X","/Westford","")&IF(ISBLANK(AC7),""," "&AC7) &IF(OR(B7="Street Crossing",B7="Witness")," "&K7,"") -> Acton/Boxborough/Littleton | B7: Corner | C7: X | D7: X | K7: Central Street | L7: Newtown Road | M7: Rte 2 Exit 115 (Newtown/Central Street) | N7: Not Found | O7: 45792 | P7: Looked a couple of times, not found yet. Boxborough reports it is missing. Coordinate location is the grassy area between lanes of the exits. Unlikely to have survived the construction of Rte 2. | Q7: ..a rough split granite monument, triangular in shape, marked A B L. and situated at a junction of walls, about one-half mile southwest of Fort pond and about 680 feet southeast of the West Acton road | S7: State | T7: 42.500186 | U7: =ABS(TRUNC(T7)) -> 42 | V7: =TRUNC(ABS(T7-TRUNC(T7))*60) -> 30 | W7: =(T7 -(U7+V7/60))*60*60 -> 0.669654 | X7: -71.473529 | Y7: =ABS(TRUNC(X7)) -> 71 | Z7: =TRUNC(ABS(X7-TRUNC(X7))*60) -> 28 | AA7: =(ABS(X7) -(Y7+Z7/60))*60*60 -> 24.706186 | AB7: =IF(ISBLANK(T7),"","https://openstreetmap.org/?mlat="&T7&"&mlon="&X7&"#map=16/"&T7&"/"&X7) -> https://openstreetmap.org/?mlat=42.5001860150001&mlon=-71.473529496#map=16/42.5001860150001/-71.473529496 | AD7: 36 | AE7: See if MassDOT has records.
A8: ="Acton"&IF(C8="X","/Boxborough","")&IF(F8="X","/Carlisle","")&IF(G8="X","/Concord","")&IF(D8="X","/Littleton","")&IF(I8="X","/Maynard","")&IF(J8="X","/Stow","")&IF(H8="X","/Sudbury","")&IF(E8="X","/Westford","")&IF(ISBLANK(AC8),""," "&AC8) &IF(OR(B8="Street Crossing",B8="Witness")," "&K8,"") -> Acton/Boxborough/Stow | B8: Corner | C8: X | J8: X | K8: Ethan Allen Drive | M8: Watertower at end of Ethan Allen Dr. | N8: Painted | O8: 45916 | P8: walk up trail from end of Ethan Allen Drive | Q8: an irregularly-shaped field stone marked A B S and situated at an intersection of three walls, in the corner of an open pasture belonging to Mr. Wetherbee, near the brow of Flagg's hill. | R8: has a dead tree impinging on the monument, removed 9/16/25 | S8: State | T8: 42.463784 | U8: =ABS(TRUNC(T8)) -> 42 | V8: =TRUNC(ABS(T8-TRUNC(T8))*60) -> 27 | W8: =(T8 -(U8+V8/60))*60*60 -> 49.621504 | X8: -71.498548 | Y8: =ABS(TRUNC(X8)) -> 71 | Z8: =TRUNC(ABS(X8-TRUNC(X8))*60) -> 29 | AA8: =(ABS(X8) -(Y8+Z8/60))*60*60 -> 54.771738 | AB8: =IF(ISBLANK(T8),"","https://openstreetmap.org/?mlat="&T8&"&mlon="&X8&"#map=16/"&T8&"/"&X8) -> https://openstreetmap.org/?mlat=42.4637837510001&mlon=-71.498547705#map=16/42.4637837510001/-71.498547705 | AD8: 42 | AE8: See if Acton, Littleton and Stow want to participate in planning, funding, and implementing a repair of the lean.
A9: ="Acton"&IF(C9="X","/Boxborough","")&IF(F9="X","/Carlisle","")&IF(G9="X","/Concord","")&IF(D9="X","/Littleton","")&IF(I9="X","/Maynard","")&IF(J9="X","/Stow","")&IF(H9="X","/Sudbury","")&IF(E9="X","/Westford","")&IF(ISBLANK(AC9),""," "&AC9) &IF(OR(B9="Street Crossing",B9="Witness")," "&K9,"") -> Acton/Carlisle 1 | B9: Corner | F9: X | K9: Triangle Farm Road | M9: Camp Acton | N9: Painted | O9: 45838 | P9: In woods on red trail connecting Acton and Carlisle conservation lands | Q9: a rough split granite monument marked A C and situated in thick oak and maple woods, opposite a junction of walls | S9: State | T9: 42.506829 | U9: =ABS(TRUNC(T9)) -> 42 | V9: =TRUNC(ABS(T9-TRUNC(T9))*60) -> 30 | W9: =(T9 -(U9+V9/60))*60*60 -> 24.583349 | X9: -71.391564 | Y9: =ABS(TRUNC(X9)) -> 71 | Z9: =TRUNC(ABS(X9-TRUNC(X9))*60) -> 23 | AA9: =(ABS(X9) -(Y9+Z9/60))*60*60 -> 29.63107 | AB9: =IF(ISBLANK(T9),"","https://openstreetmap.org/?mlat="&T9&"&mlon="&X9&"#map=16/"&T9&"/"&X9) -> https://openstreetmap.org/?mlat=42.5068287080001&mlon=-71.391564186#map=16/42.5068287080001/-71.391564186 | AC9: 1 | AD9: 14
A10: ="Acton"&IF(C10="X","/Boxborough","")&IF(F10="X","/Carlisle","")&IF(G10="X","/Concord","")&IF(D10="X","/Littleton","")&IF(I10="X","/Maynard","")&IF(J10="X","/Stow","")&IF(H10="X","/Sudbury","")&IF(E10="X","/Westford","")&IF(ISBLANK(AC10),""," "&AC10) &IF(OR(B10="Street Crossing",B10="Witness")," "&K10,"") -> Acton/Carlisle 2 | B10: Corner | F10: X | K10: Carlisle Road | L10: Acton Street | N10: Painted | O10: 45838 | P10: right at intersection, north side | Q10: roadstone...northerly side of Acton street [in 1904 this was just called a road marker, but now it's a corner] | S10: State | T10: 42.526345 | U10: =ABS(TRUNC(T10)) -> 42 | V10: =TRUNC(ABS(T10-TRUNC(T10))*60) -> 31 | W10: =(T10 -(U10+V10/60))*60*60 -> 34.841305 | X10: -71.397947 | Y10: =ABS(TRUNC(X10)) -> 71 | Z10: =TRUNC(ABS(X10-TRUNC(X10))*60) -> 23 | AA10: =(ABS(X10) -(Y10+Z10/60))*60*60 -> 52.609722 | AB10: =IF(ISBLANK(T10),"","https://openstreetmap.org/?mlat="&T10&"&mlon="&X10&"#map=16/"&T10&"/"&X10) -> https://openstreetmap.org/?mlat=42.526344807&mlon=-71.397947145#map=16/42.526344807/-71.397947145 | AC10: 2 | AD10: 15
A11: ="Acton"&IF(C11="X","/Boxborough","")&IF(F11="X","/Carlisle","")&IF(G11="X","/Concord","")&IF(D11="X","/Littleton","")&IF(I11="X","/Maynard","")&IF(J11="X","/Stow","")&IF(H11="X","/Sudbury","")&IF(E11="X","/Westford","")&IF(ISBLANK(AC11),""," "&AC11) &IF(OR(B11="Street Crossing",B11="Witness")," "&K11,"") -> Acton/Carlisle Main Street (Rte 27) | B11: Street Crossing | F11: X | K11: Main Street (Rte 27) | L11: Acton Road | N11: Painted | O11: 45838 | P11: 10 meters south of Acton/WESTFORD sign, on East side (1904 suggests there might also be one on the west side) | Q11: roadstones on the westerly and easterly sides of the North Acton road | R11: "Acton: 1996" partially buried and snapped off | S11: GIS iPad | T11: 42.526336 | U11: =IF(ISBLANK(T11),"",ABS(TRUNC(T11))) -> 42 | V11: =IF(ISBLANK(T11),"",TRUNC(ABS(T11-TRUNC(T11))*60)) -> 31 | W11: =IF(ISBLANK(T11),"",(T11 -(U11+V11/60))*60*60) -> 34.8096 | X11: -71.397946 | Y11: =IF(ISBLANK(X11),"",ABS(TRUNC(X11))) -> 71 | Z11: =IF(ISBLANK(X11),"",TRUNC(ABS(X11-TRUNC(X11))*60)) -> 23 | AA11: =IF(ISBLANK(X11),"",(ABS(X11) -(Y11+Z11/60))*60*60) -> 52.6056 | AB11: =IF(ISBLANK(T11),"","https://openstreetmap.org/?mlat="&T11&"&mlon="&X11&"#map=16/"&T11&"/"&X11) -> https://openstreetmap.org/?mlat=42.526336&mlon=-71.397946#map=16/42.526336/-71.397946 | AD11: 16 | AE11: See if Acton and Carlisle want to cooperate on a fix.
A12: ="Acton"&IF(C12="X","/Boxborough","")&IF(F12="X","/Carlisle","")&IF(G12="X","/Concord","")&IF(D12="X","/Littleton","")&IF(I12="X","/Maynard","")&IF(J12="X","/Stow","")&IF(H12="X","/Sudbury","")&IF(E12="X","/Westford","")&IF(ISBLANK(AC12),""," "&AC12) &IF(OR(B12="Street Crossing",B12="Witness")," "&K12,"") -> Acton/Carlisle unknown road | B12: Street Crossing | F12: X | K12: unknown road | N12: Documented | P12: Noted on 11/29/25 from 1904 listing. Haven't looked for it yet: may have access from Ben's Woods. | Q12: linestone between the corner of Acton - Concord- Carlisle and Acton - Carlisle | AB12: =IF(ISBLANK(T12),"","https://openstreetmap.org/?mlat="&T12&"&mlon="&X12&"#map=16/"&T12&"/"&X12) | AD12: 13 | AE12: Survey at edge of Ben's Woods.
A13: ="Acton"&IF(C13="X","/Boxborough","")&IF(F13="X","/Carlisle","")&IF(G13="X","/Concord","")&IF(D13="X","/Littleton","")&IF(I13="X","/Maynard","")&IF(J13="X","/Stow","")&IF(H13="X","/Sudbury","")&IF(E13="X","/Westford","")&IF(ISBLANK(AC13),""," "&AC13) &IF(OR(B13="Street Crossing",B13="Witness")," "&K13,"") -> Acton/Carlisle/Concord Pope Road Witness Marker | B13: Witness | F13: X | G13: X | K13: Pope Road Witness Marker | M13: 394 Pope Road | N13: Painted | O13: 45838 | P13: corner is in house, but the actual bound has been offset to a stone wall: need permission of owner before visiting | Q13: a rough granite monument marked A C C and situated on the easterly slope of a hill covered with savins and ground hemlock, about 125 feet southwest of a wall on the westerly side of the road leading from East Acton to Carlisle | R13: The Witness Monument is dated 2007. The coordinates shown are for the monument. The actual corner is at 42.50447314, -71.38494746 (state bounds, WGS84). | S13: map estimate | T13: 42.504159 | U13: =ABS(TRUNC(T13)) -> 42 | V13: =TRUNC(ABS(T13-TRUNC(T13))*60) -> 30 | W13: =(T13 -(U13+V13/60))*60*60 -> 14.9724 | X13: -71.385158 | Y13: =ABS(TRUNC(X13)) -> 71 | Z13: =TRUNC(ABS(X13-TRUNC(X13))*60) -> 23 | AA13: =(ABS(X13) -(Y13+Z13/60))*60*60 -> 6.5688 | AB13: =IF(ISBLANK(T13),"","https://openstreetmap.org/?mlat="&T13&"&mlon="&X13&"#map=16/"&T13&"/"&X13) -> https://openstreetmap.org/?mlat=42.504159&mlon=-71.385158#map=16/42.504159/-71.385158 | AD13: 12
A14: ="Acton"&IF(C14="X","/Boxborough","")&IF(F14="X","/Carlisle","")&IF(G14="X","/Concord","")&IF(D14="X","/Littleton","")&IF(I14="X","/Maynard","")&IF(J14="X","/Stow","")&IF(H14="X","/Sudbury","")&IF(E14="X","/Westford","")&IF(ISBLANK(AC14),""," "&AC14) &IF(OR(B14="Street Crossing",B14="Witness")," "&K14,"") -> Acton/Carlisle/Westford | B14: Corner | E14: X | F14: X | K14: Main Street (Rte 27) | M14: Butter Brook Golf Club | N14: Painted | O14: 45838 | P14: Up an embankment on the west side of Main St. Golf course is visible from marker. Not to be confused with a Carlisle/Westford Main Street (Rte 27) marker that is closer to Rte 27. That marker only has a single Carlisle mark and no others. | Q14: a rough split granite monument marked A W C and situated in a pine grove, about 825 feet southerly from the Carlisle railway station | S14: State | T14: 42.534025 | U14: =ABS(TRUNC(T14)) -> 42 | V14: =TRUNC(ABS(T14-TRUNC(T14))*60) -> 32 | W14: =(T14 -(U14+V14/60))*60*60 -> 2.4903096 | X14: -71.399515 | Y14: =ABS(TRUNC(X14)) -> 71 | Z14: =TRUNC(ABS(X14-TRUNC(X14))*60) -> 23 | AA14: =(ABS(X14) -(Y14+Z14/60))*60*60 -> 58.25521 | AB14: =IF(ISBLANK(T14),"","https://openstreetmap.org/?mlat="&T14&"&mlon="&X14&"#map=16/"&T14&"/"&X14) -> https://openstreetmap.org/?mlat=42.534025086&mlon=-71.399515336#map=16/42.534025086/-71.399515336 | AD14: 17
A15: ="Acton"&IF(C15="X","/Boxborough","")&IF(F15="X","/Carlisle","")&IF(G15="X","/Concord","")&IF(D15="X","/Littleton","")&IF(I15="X","/Maynard","")&IF(J15="X","/Stow","")&IF(H15="X","/Sudbury","")&IF(E15="X","/Westford","")&IF(ISBLANK(AC15),""," "&AC15) &IF(OR(B15="Street Crossing",B15="Witness")," "&K15,"") -> Acton/Concord Great Road | B15: Street Crossing | G15: X | K15: Great Road | M15: Life Care of Acton | N15: Painted | O15: 45838 | Q15: on the northerly side of Elm street, sometimes called the Acton road | R15: new marker installed by Concord in 2017 with a line on top following the boundary line | S15: GIS iPad | T15: 42.473365 | U15: =IF(ISBLANK(T15),"",ABS(TRUNC(T15))) -> 42 | V15: =IF(ISBLANK(T15),"",TRUNC(ABS(T15-TRUNC(T15))*60)) -> 28 | W15: =IF(ISBLANK(T15),"",(T15 -(U15+V15/60))*60*60) -> 24.114 | X15: -71.405893 | Y15: =ABS(TRUNC(X15)) -> 71 | Z15: =TRUNC(ABS(X15-TRUNC(X15))*60) -> 24 | AA15: =(ABS(X15) -(Y15+Z15/60))*60*60 -> 21.2148 | AB15: =IF(ISBLANK(T15),"","https://openstreetmap.org/?mlat="&T15&"&mlon="&X15&"#map=16/"&T15&"/"&X15) -> https://openstreetmap.org/?mlat=42.473365&mlon=-71.405893#map=16/42.473365/-71.405893 | AD15: 8
A16: ="Acton"&IF(C16="X","/Boxborough","")&IF(F16="X","/Carlisle","")&IF(G16="X","/Concord","")&IF(D16="X","/Littleton","")&IF(I16="X","/Maynard","")&IF(J16="X","/Stow","")&IF(H16="X","/Sudbury","")&IF(E16="X","/Westford","")&IF(ISBLANK(AC16),""," "&AC16) &IF(OR(B16="Street Crossing",B16="Witness")," "&K16,"") -> Acton/Concord Keefe Road | B16: Street Crossing | G16: X | K16: Keefe Road | L16: Great Road | M16: International Collision Center | N16: Found | O16: 45989 | P16: Keefe Road used to go into Concord | Q16: on the northeasterly side of a cross road between the Acton road and Worcester turnpike | R16: found when too cold to paint | S16: GIS iPad | T16: 42.472315 | U16: =IF(ISBLANK(T16),"",ABS(TRUNC(T16))) -> 42 | V16: =IF(ISBLANK(T16),"",TRUNC(ABS(T16-TRUNC(T16))*60)) -> 28 | W16: =IF(ISBLANK(T16),"",(T16 -(U16+V16/60))*60*60) -> 20.334 | X16: -71.406597 | Y16: =ABS(TRUNC(X16)) -> 71 | Z16: =TRUNC(ABS(X16-TRUNC(X16))*60) -> 24 | AA16: =(ABS(X16) -(Y16+Z16/60))*60*60 -> 23.7492 | AB16: =IF(ISBLANK(T16),"","https://openstreetmap.org/?mlat="&T16&"&mlon="&X16&"#map=16/"&T16&"/"&X16) -> https://openstreetmap.org/?mlat=42.472315&mlon=-71.406597#map=16/42.472315/-71.406597 | AD16: 7 | AE16: Paint the monument.
A17: ="Acton"&IF(C17="X","/Boxborough","")&IF(F17="X","/Carlisle","")&IF(G17="X","/Concord","")&IF(D17="X","/Littleton","")&IF(I17="X","/Maynard","")&IF(J17="X","/Stow","")&IF(H17="X","/Sudbury","")&IF(E17="X","/Westford","")&IF(ISBLANK(AC17),""," "&AC17) &IF(OR(B17="Street Crossing",B17="Witness")," "&K17,"") -> Acton/Concord Knox Trail | B17: Street Crossing | G17: X | K17: Knox Trail | N17: Not Found | O17: 45770 | P17: no road in that location on early 20th century maps: probably never got a monument | Q17: no | S17: map estimate | T17: 42.442202 | U17: =IF(ISBLANK(T17),"",ABS(TRUNC(T17))) -> 42 | V17: =IF(ISBLANK(T17),"",TRUNC(ABS(T17-TRUNC(T17))*60)) -> 26 | W17: =IF(ISBLANK(T17),"",(T17 -(U17+V17/60))*60*60) -> 31.9272 | X17: -71.426872 | Y17: =ABS(TRUNC(X17)) -> 71 | Z17: =TRUNC(ABS(X17-TRUNC(X17))*60) -> 25 | AA17: =(ABS(X17) -(Y17+Z17/60))*60*60 -> 36.7392 | AB17: =IF(ISBLANK(T17),"","https://openstreetmap.org/?mlat="&T17&"&mlon="&X17&"#map=16/"&T17&"/"&X17) -> https://openstreetmap.org/?mlat=42.442202&mlon=-71.426872#map=16/42.442202/-71.426872 | AD17: 3 | AE17: Tell Concord. It seems they looked on Knox Trail for the 'Parmenter Road'.
A18: ="Acton"&IF(C18="X","/Boxborough","")&IF(F18="X","/Carlisle","")&IF(G18="X","/Concord","")&IF(D18="X","/Littleton","")&IF(I18="X","/Maynard","")&IF(J18="X","/Stow","")&IF(H18="X","/Sudbury","")&IF(E18="X","/Westford","")&IF(ISBLANK(AC18),""," "&AC18) &IF(OR(B18="Street Crossing",B18="Witness")," "&K18,"") -> Acton/Concord Laws Brook Road | B18: Street Crossing | G18: X | K18: Laws Brook Road | N18: Painted | O18: 45838 | P18: south side of road, near sign | Q18: on the southerly side of Laws Brook road | S18: GIS iPad | T18: 42.459859 | U18: =IF(ISBLANK(T18),"",ABS(TRUNC(T18))) -> 42 | V18: =IF(ISBLANK(T18),"",TRUNC(ABS(T18-TRUNC(T18))*60)) -> 27 | W18: =IF(ISBLANK(T18),"",(T18 -(U18+V18/60))*60*60) -> 35.4924 | X18: -71.414985 | Y18: =IF(ISBLANK(X18),"",ABS(TRUNC(X18))) -> 71 | Z18: =IF(ISBLANK(X18),"",TRUNC(ABS(X18-TRUNC(X18))*60)) -> 24 | AA18: =IF(ISBLANK(X18),"",(ABS(X18) -(Y18+Z18/60))*60*60) -> 53.946 | AB18: =IF(ISBLANK(T18),"","https://openstreetmap.org/?mlat="&T18&"&mlon="&X18&"#map=16/"&T18&"/"&X18) -> https://openstreetmap.org/?mlat=42.459859&mlon=-71.414985#map=16/42.459859/-71.414985 | AD18: 5
A19: ="Acton"&IF(C19="X","/Boxborough","")&IF(F19="X","/Carlisle","")&IF(G19="X","/Concord","")&IF(D19="X","/Littleton","")&IF(I19="X","/Maynard","")&IF(J19="X","/Stow","")&IF(H19="X","/Sudbury","")&IF(E19="X","/Westford","")&IF(ISBLANK(AC19),""," "&AC19) &IF(OR(B19="Street Crossing",B19="Witness")," "&K19,"") -> Acton/Concord Old Stow Road | B19: Street Crossing | G19: X | K19: Old Stow Road | M19: Old Stow Rd CR, railroad | N19: Painted | O19: Sep 24, 2025 (2) | P19: old road is now a trail | Q19: on the northerly side of the Parmenter road | S19: GIS iPad | T19: 42.456849 | U19: =IF(ISBLANK(T19),"",ABS(TRUNC(T19))) -> 42 | V19: =IF(ISBLANK(T19),"",TRUNC(ABS(T19-TRUNC(T19))*60)) -> 27 | W19: =IF(ISBLANK(T19),"",(T19 -(U19+V19/60))*60*60) -> 24.6564 | X19: -71.417005 | Y19: =IF(ISBLANK(X19),"",ABS(TRUNC(X19))) -> 71 | Z19: =IF(ISBLANK(X19),"",TRUNC(ABS(X19-TRUNC(X19))*60)) -> 25 | AA19: =IF(ISBLANK(X19),"",(ABS(X19) -(Y19+Z19/60))*60*60) -> 1.218 | AB19: =IF(ISBLANK(T19),"","https://openstreetmap.org/?mlat="&T19&"&mlon="&X19&"#map=16/"&T19&"/"&X19) -> https://openstreetmap.org/?mlat=42.456849&mlon=-71.417005#map=16/42.456849/-71.417005 | AD19: 4
A20: ="Acton"&IF(C20="X","/Boxborough","")&IF(F20="X","/Carlisle","")&IF(G20="X","/Concord","")&IF(D20="X","/Littleton","")&IF(I20="X","/Maynard","")&IF(J20="X","/Stow","")&IF(H20="X","/Sudbury","")&IF(E20="X","/Westford","")&IF(ISBLANK(AC20),""," "&AC20) &IF(OR(B20="Street Crossing",B20="Witness")," "&K20,"") -> Acton/Concord Pope Road | B20: Street Crossing | G20: X | K20: Pope Road | M20: 380 Pope Road | N20: Painted | O20: 45838 | Q20: roadstones on the easterly side of the road leading to East Acton | S20: GIS iPad | T20: 42.503316 | U20: =IF(ISBLANK(T20),"",ABS(TRUNC(T20))) -> 42 | V20: =IF(ISBLANK(T20),"",TRUNC(ABS(T20-TRUNC(T20))*60)) -> 30 | W20: =IF(ISBLANK(T20),"",(T20 -(U20+V20/60))*60*60) -> 11.9376 | X20: -71.385706 | Y20: =IF(ISBLANK(X20),"",ABS(TRUNC(X20))) -> 71 | Z20: =IF(ISBLANK(X20),"",TRUNC(ABS(X20-TRUNC(X20))*60)) -> 23 | AA20: =IF(ISBLANK(X20),"",(ABS(X20) -(Y20+Z20/60))*60*60) -> 8.5416 | AB20: =IF(ISBLANK(T20),"","https://openstreetmap.org/?mlat="&T20&"&mlon="&X20&"#map=16/"&T20&"/"&X20) -> https://openstreetmap.org/?mlat=42.503316&mlon=-71.385706#map=16/42.503316/-71.385706 | AD20: 11
A21: ="Acton"&IF(C21="X","/Boxborough","")&IF(F21="X","/Carlisle","")&IF(G21="X","/Concord","")&IF(D21="X","/Littleton","")&IF(I21="X","/Maynard","")&IF(J21="X","/Stow","")&IF(H21="X","/Sudbury","")&IF(E21="X","/Westford","")&IF(ISBLANK(AC21),""," "&AC21) &IF(OR(B21="Street Crossing",B21="Witness")," "&K21,"") -> Acton/Concord Powder Mill Road (Rte 62) | B21: Street Crossing | G21: X | K21: Powder Mill Road (Rte 62) | N21: Not Found | O21: 45770 | P21: found location marker but no monument, unless it is buried: Concord found it in 2017 | Q21: on the northerly side of Main street Concord, called Powder Mills road in Acton. | S21: map estimate | T21: 42.441875 | U21: =ABS(TRUNC(T21)) -> 42 | V21: =TRUNC(ABS(T21-TRUNC(T21))*60) -> 26 | W21: =(T21 -(U21+V21/60))*60*60 -> 30.75 | X21: -71.427081 | Y21: =ABS(TRUNC(X21)) -> 71 | Z21: =TRUNC(ABS(X21-TRUNC(X21))*60) -> 25 | AA21: =(ABS(X21) -(Y21+Z21/60))*60*60 -> 37.4916 | AB21: =IF(ISBLANK(T21),"","https://openstreetmap.org/?mlat="&T21&"&mlon="&X21&"#map=16/"&T21&"/"&X21) -> https://openstreetmap.org/?mlat=42.441875&mlon=-71.427081#map=16/42.441875/-71.427081 | AD21: 2 | AE21: Ask Concord for more details.
A22: ="Acton"&IF(C22="X","/Boxborough","")&IF(F22="X","/Carlisle","")&IF(G22="X","/Concord","")&IF(D22="X","/Littleton","")&IF(I22="X","/Maynard","")&IF(J22="X","/Stow","")&IF(H22="X","/Sudbury","")&IF(E22="X","/Westford","")&IF(ISBLANK(AC22),""," "&AC22) &IF(OR(B22="Street Crossing",B22="Witness")," "&K22,"") -> Acton/Concord Rte 2 | B22: Street Crossing | G22: X | K22: Rte 2 | M22: Rail Trail bridge | N22: Not Found | O22: 45405 | P22: a variety of possible markers were located, but none were marked or in right location | Q22: on the southerly side of Worcester turnpike | S22: map estimate | T22: 42.469254 | U22: =IF(ISBLANK(T22),"",ABS(TRUNC(T22))) -> 42 | V22: =IF(ISBLANK(T22),"",TRUNC(ABS(T22-TRUNC(T22))*60)) -> 28 | W22: =IF(ISBLANK(T22),"",(T22 -(U22+V22/60))*60*60) -> 9.3144 | X22: -71.408660 | Y22: =ABS(TRUNC(X22)) -> 71 | Z22: =TRUNC(ABS(X22-TRUNC(X22))*60) -> 24 | AA22: =(ABS(X22) -(Y22+Z22/60))*60*60 -> 31.176 | AB22: =IF(ISBLANK(T22),"","https://openstreetmap.org/?mlat="&T22&"&mlon="&X22&"#map=16/"&T22&"/"&X22) -> https://openstreetmap.org/?mlat=42.469254&mlon=-71.408660#map=16/42.469254/-71.408660 | AD22: 6 | AE22: See if Mass DOT has any records.
A23: ="Acton"&IF(C23="X","/Boxborough","")&IF(F23="X","/Carlisle","")&IF(G23="X","/Concord","")&IF(D23="X","/Littleton","")&IF(I23="X","/Maynard","")&IF(J23="X","/Stow","")&IF(H23="X","/Sudbury","")&IF(E23="X","/Westford","")&IF(ISBLANK(AC23),""," "&AC23) &IF(OR(B23="Street Crossing",B23="Witness")," "&K23,"") -> Acton/Concord Spencer Brook Road | B23: Street Crossing | G23: X | K23: Spencer Brook Road | N23: Painted | O23: 45838 | P23: close to Pope rd, on north side | Q23: at the junction of the same road [road to East Acton] and a cross road leading to the Lowell road | S23: GIS iPad | T23: 42.502313 | U23: =IF(ISBLANK(T23),"",ABS(TRUNC(T23))) -> 42 | V23: =IF(ISBLANK(T23),"",TRUNC(ABS(T23-TRUNC(T23))*60)) -> 30 | W23: =IF(ISBLANK(T23),"",(T23 -(U23+V23/60))*60*60) -> 8.3268 | X23: -71.386401 | Y23: =ABS(TRUNC(X23)) -> 71 | Z23: =TRUNC(ABS(X23-TRUNC(X23))*60) -> 23 | AA23: =(ABS(X23) -(Y23+Z23/60))*60*60 -> 11.0436 | AB23: =IF(ISBLANK(T23),"","https://openstreetmap.org/?mlat="&T23&"&mlon="&X23&"#map=16/"&T23&"/"&X23) -> https://openstreetmap.org/?mlat=42.502313&mlon=-71.386401#map=16/42.502313/-71.386401 | AD23: 10
A24: ="Acton"&IF(C24="X","/Boxborough","")&IF(F24="X","/Carlisle","")&IF(G24="X","/Concord","")&IF(D24="X","/Littleton","")&IF(I24="X","/Maynard","")&IF(J24="X","/Stow","")&IF(H24="X","/Sudbury","")&IF(E24="X","/Westford","")&IF(ISBLANK(AC24),""," "&AC24) &IF(OR(B24="Street Crossing",B24="Witness")," "&K24,"") -> Acton/Concord Strawberry Hill Road | B24: Street Crossing | G24: X | K24: Strawberry Hill Road | N24: Painted | O24: 45838 | Q24: on the northerly side of the Strawberry hill road | S24: GIS iPad | T24: 42.491233 | U24: =IF(ISBLANK(T24),"",ABS(TRUNC(T24))) -> 42 | V24: =IF(ISBLANK(T24),"",TRUNC(ABS(T24-TRUNC(T24))*60)) -> 29 | W24: =IF(ISBLANK(T24),"",(T24 -(U24+V24/60))*60*60) -> 28.4388 | X24: -71.393807 | Y24: =ABS(TRUNC(X24)) -> 71 | Z24: =TRUNC(ABS(X24-TRUNC(X24))*60) -> 23 | AA24: =(ABS(X24) -(Y24+Z24/60))*60*60 -> 37.7052 | AB24: =IF(ISBLANK(T24),"","https://openstreetmap.org/?mlat="&T24&"&mlon="&X24&"#map=16/"&T24&"/"&X24) -> https://openstreetmap.org/?mlat=42.491233&mlon=-71.393807#map=16/42.491233/-71.393807 | AD24: 9
A25: ="Acton"&IF(C25="X","/Boxborough","")&IF(F25="X","/Carlisle","")&IF(G25="X","/Concord","")&IF(D25="X","/Littleton","")&IF(I25="X","/Maynard","")&IF(J25="X","/Stow","")&IF(H25="X","/Sudbury","")&IF(E25="X","/Westford","")&IF(ISBLANK(AC25),""," "&AC25) &IF(OR(B25="Street Crossing",B25="Witness")," "&K25,"") -> Acton/Concord/Maynard/Sudbury | B25: Corner | G25: X | H25: X | I25: X | K25: Old Powder Mill Road | M25: Acton Senior Center, Maynard/Acton substation | N25: Painted | O25: Jul 24, 2025 (1) | P25: next to substation | Q25: rough split granite monument marked A C M and situated on the south westerly side of the road leading from South Acton to North Sudbury, back of the American Powder Mill | R25: It appears that Sudbury wrote their initial and their years on the west side, next to Acton on the north, leaving latecomer Maynard (1871) only the south side to write on, even though Maynard should be between Sudbury and Acton. | S25: State | T25: 42.436948 | U25: =ABS(TRUNC(T25)) -> 42 | V25: =TRUNC(ABS(T25-TRUNC(T25))*60) -> 26 | W25: =(T25 -(U25+V25/60))*60*60 -> 13.012778 | X25: -71.430395 | Y25: =ABS(TRUNC(X25)) -> 71 | Z25: =TRUNC(ABS(X25-TRUNC(X25))*60) -> 25 | AA25: =(ABS(X25) -(Y25+Z25/60))*60*60 -> 49.421204 | AB25: =IF(ISBLANK(T25),"","https://openstreetmap.org/?mlat="&T25&"&mlon="&X25&"#map=16/"&T25&"/"&X25) -> https://openstreetmap.org/?mlat=42.436947994&mlon=-71.430394779#map=16/42.436947994/-71.430394779 | AD25: 1
A26: ="Acton"&IF(C26="X","/Boxborough","")&IF(F26="X","/Carlisle","")&IF(G26="X","/Concord","")&IF(D26="X","/Littleton","")&IF(I26="X","/Maynard","")&IF(J26="X","/Stow","")&IF(H26="X","/Sudbury","")&IF(E26="X","/Westford","")&IF(ISBLANK(AC26),""," "&AC26) &IF(OR(B26="Street Crossing",B26="Witness")," "&K26,"") -> Acton/Littleton 1 | B26: Corner | D26: X | K26: Nashoba Road | M26: Nagog Pond, North Shore | N26: Couldn't paint | O26: 45810 | P26: next to stone wall near end of Nashoba Road | Q26: corner 1, a rough split granite monument of irregular shape marked A L 1831 and situated at the northerly end of Nagog pond, on the northeasterly side of the road leading from North Acton to Littletown [sic] | R26: Lying on ground, too difficult to paint, possibly a good candidate for rescue. A note from Andy Curran of Littleton: "The triangle at the road intersection used to have granite marker in it and may have been inscribed with an L and an A. Many of us remember the stone, which disappeared during roadwork, probably sometime in the 1970s. My guess is that the highway department got careless and broke it and dumped it on the ditch, where you found it." | S26: State | T26: 42.522179 | U26: =ABS(TRUNC(T26)) -> 42 | V26: =TRUNC(ABS(T26-TRUNC(T26))*60) -> 31 | W26: =(T26 -(U26+V26/60))*60*60 -> 19.844933 | X26: -71.435018 | Y26: =ABS(TRUNC(X26)) -> 71 | Z26: =TRUNC(ABS(X26-TRUNC(X26))*60) -> 26 | AA26: =(ABS(X26) -(Y26+Z26/60))*60*60 -> 6.0644616 | AB26: =IF(ISBLANK(T26),"","https://openstreetmap.org/?mlat="&T26&"&mlon="&X26&"#map=16/"&T26&"/"&X26) -> https://openstreetmap.org/?mlat=42.5221791480001&mlon=-71.435017906#map=16/42.5221791480001/-71.435017906 | AC26: 1 | AD26: 26 | AE26: Work with Littleton on planning, funding, and implementing a repair.
A27: ="Acton"&IF(C27="X","/Boxborough","")&IF(F27="X","/Carlisle","")&IF(G27="X","/Concord","")&IF(D27="X","/Littleton","")&IF(I27="X","/Maynard","")&IF(J27="X","/Stow","")&IF(H27="X","/Sudbury","")&IF(E27="X","/Westford","")&IF(ISBLANK(AC27),""," "&AC27) &IF(OR(B27="Street Crossing",B27="Witness")," "&K27,"") -> Acton/Littleton 2 | B27: Corner | D27: X | K27: Nagog Hill Road | M27: Nagog Pond South Shore | N27: Painted | O27: 45810 | P27: near bottom of AWD land: roughly follow tree across path near pond uphill | Q27: corner 2, a rough split granite monument of irregular shape marked A L 1831, and situated in heavy maple, oak and chestnut woods, about 288 feet from the southwesterly shore of Nagog pond. | S27: State | T27: 42.509069 | U27: =ABS(TRUNC(T27)) -> 42 | V27: =TRUNC(ABS(T27-TRUNC(T27))*60) -> 30 | W27: =(T27 -(U27+V27/60))*60*60 -> 32.646827 | X27: -71.44394 | Y27: =ABS(TRUNC(X27)) -> 71 | Z27: =TRUNC(ABS(X27-TRUNC(X27))*60) -> 26 | AA27: =(ABS(X27) -(Y27+Z27/60))*60*60 -> 38.185091 | AB27: =IF(ISBLANK(T27),"","https://openstreetmap.org/?mlat="&T27&"&mlon="&X27&"#map=16/"&T27&"/"&X27) -> https://openstreetmap.org/?mlat=42.509068563&mlon=-71.443940303#map=16/42.509068563/-71.443940303 | AC27: 2 | AD27: 28
A28: ="Acton"&IF(C28="X","/Boxborough","")&IF(F28="X","/Carlisle","")&IF(G28="X","/Concord","")&IF(D28="X","/Littleton","")&IF(I28="X","/Maynard","")&IF(J28="X","/Stow","")&IF(H28="X","/Sudbury","")&IF(E28="X","/Westford","")&IF(ISBLANK(AC28),""," "&AC28) &IF(OR(B28="Street Crossing",B28="Witness")," "&K28,"") -> Acton/Littleton Countryside Road | B28: Street Crossing | D28: X | K28: Countryside Road | L28: Countryside Road | N28: Not Found | O28: 45741 | P28: Found town line stone wall, but big missing portion may be where monument was? Or perhaps road is new enough that monument was never placed. | Q28: no | S28: map estimate | T28: 42.50236 | U28: =ABS(TRUNC(T28)) -> 42 | V28: =TRUNC(ABS(T28-TRUNC(T28))*60) -> 30 | W28: =(T28 -(U28+V28/60))*60*60 -> 8.496 | X28: -71.46624 | Y28: =IF(ISBLANK(X28),"",ABS(TRUNC(X28))) -> 71 | Z28: =IF(ISBLANK(X28),"",TRUNC(ABS(X28-TRUNC(X28))*60)) -> 27 | AA28: =IF(ISBLANK(X28),"",(ABS(X28) -(Y28+Z28/60))*60*60) -> 58.464 | AB28: =IF(ISBLANK(T28),"","https://openstreetmap.org/?mlat="&T28&"&mlon="&X28&"#map=16/"&T28&"/"&X28) -> https://openstreetmap.org/?mlat=42.50236&mlon=-71.46624#map=16/42.50236/-71.46624 | AD28: 33 | AE28: Acton to make decision on whether any new monuments will be added.
A29: ="Acton"&IF(C29="X","/Boxborough","")&IF(F29="X","/Carlisle","")&IF(G29="X","/Concord","")&IF(D29="X","/Littleton","")&IF(I29="X","/Maynard","")&IF(J29="X","/Stow","")&IF(H29="X","/Sudbury","")&IF(E29="X","/Westford","")&IF(ISBLANK(AC29),""," "&AC29) &IF(OR(B29="Street Crossing",B29="Witness")," "&K29,"") -> Acton/Littleton Fort Pond Road | B29: Street Crossing | D29: X | K29: Fort Pond Road | L29: Fort Pond Road | N29: Painted | O29: 45810 | P29: What was found is most likely the westerly of two monuments. The easterly monument would have been much closer to the actual boundary line. | Q29: the easterly and westerly sides of the Cash road | S29: GIS iPad | T29: 42.505986 | U29: =ABS(TRUNC(T29)) -> 42 | V29: =TRUNC(ABS(T29-TRUNC(T29))*60) -> 30 | W29: =(T29 -(U29+V29/60))*60*60 -> 21.5496 | X29: -71.454487 | Y29: =IF(ISBLANK(X29),"",ABS(TRUNC(X29))) -> 71 | Z29: =IF(ISBLANK(X29),"",TRUNC(ABS(X29-TRUNC(X29))*60)) -> 27 | AA29: =IF(ISBLANK(X29),"",(ABS(X29) -(Y29+Z29/60))*60*60) -> 16.1532 | AB29: =IF(ISBLANK(T29),"","https://openstreetmap.org/?mlat="&T29&"&mlon="&X29&"#map=16/"&T29&"/"&X29) -> https://openstreetmap.org/?mlat=42.505986&mlon=-71.454487#map=16/42.505986/-71.454487 | AD29: 30
A30: ="Acton"&IF(C30="X","/Boxborough","")&IF(F30="X","/Carlisle","")&IF(G30="X","/Concord","")&IF(D30="X","/Littleton","")&IF(I30="X","/Maynard","")&IF(J30="X","/Stow","")&IF(H30="X","/Sudbury","")&IF(E30="X","/Westford","")&IF(ISBLANK(AC30),""," "&AC30) &IF(OR(B30="Street Crossing",B30="Witness")," "&K30,"") -> Acton/Littleton Great Road | B30: Street Crossing | D30: X | K30: Great Road | L30: Great Road | N30: Not Found | O30: 45810 | P30: maybe never installed because it would have been so close to the Acton/Littleton monument? | Q30: no | S30: map estimate | T30: 42.52252 | U30: =ABS(TRUNC(T30)) -> 42 | V30: =TRUNC(ABS(T30-TRUNC(T30))*60) -> 31 | W30: =(T30 -(U30+V30/60))*60*60 -> 21.072 | X30: -71.43466 | Y30: =ABS(TRUNC(X30)) -> 71 | Z30: =TRUNC(ABS(X30-TRUNC(X30))*60) -> 26 | AA30: =(ABS(X30) -(Y30+Z30/60))*60*60 -> 4.776 | AB30: =IF(ISBLANK(T30),"","https://openstreetmap.org/?mlat="&T30&"&mlon="&X30&"#map=16/"&T30&"/"&X30) -> https://openstreetmap.org/?mlat=42.52252&mlon=-71.43466#map=16/42.52252/-71.43466 | AD30: 25
A31: ="Acton"&IF(C31="X","/Boxborough","")&IF(F31="X","/Carlisle","")&IF(G31="X","/Concord","")&IF(D31="X","/Littleton","")&IF(I31="X","/Maynard","")&IF(J31="X","/Stow","")&IF(H31="X","/Sudbury","")&IF(E31="X","/Westford","")&IF(ISBLANK(AC31),""," "&AC31) &IF(OR(B31="Street Crossing",B31="Witness")," "&K31,"") -> Acton/Littleton Lillian Road | B31: Street Crossing | D31: X | K31: Lillian Road | L31: Lillian Rd | N31: Not Found | O31: 45741 | P31: newer road: probably never placed | Q31: no | S31: map estimate | T31: 42.501133 | U31: =IF(ISBLANK(T31),"",ABS(TRUNC(T31))) -> 42 | V31: =IF(ISBLANK(T31),"",TRUNC(ABS(T31-TRUNC(T31))*60)) -> 30 | W31: =IF(ISBLANK(T31),"",(T31 -(U31+V31/60))*60*60) -> 4.0788 | X31: -71.470302 | Y31: =IF(ISBLANK(X31),"",ABS(TRUNC(X31))) -> 71 | Z31: =IF(ISBLANK(X31),"",TRUNC(ABS(X31-TRUNC(X31))*60)) -> 28 | AA31: =IF(ISBLANK(X31),"",(ABS(X31) -(Y31+Z31/60))*60*60) -> 13.0872 | AB31: =IF(ISBLANK(T31),"","https://openstreetmap.org/?mlat="&T31&"&mlon="&X31&"#map=16/"&T31&"/"&X31) -> https://openstreetmap.org/?mlat=42.501133&mlon=-71.470302#map=16/42.501133/-71.470302 | AD31: 35 | AE31: Acton to make decision on whether any new monuments will be added.
A32: ="Acton"&IF(C32="X","/Boxborough","")&IF(F32="X","/Carlisle","")&IF(G32="X","/Concord","")&IF(D32="X","/Littleton","")&IF(I32="X","/Maynard","")&IF(J32="X","/Stow","")&IF(H32="X","/Sudbury","")&IF(E32="X","/Westford","")&IF(ISBLANK(AC32),""," "&AC32) &IF(OR(B32="Street Crossing",B32="Witness")," "&K32,"") -> Acton/Littleton Nagog Hill Road | B32: Street Crossing | D32: X | K32: Nagog Hill Road | L32: Nagog Hill Road | N32: Painted | O32: 45810 | P32: right next to boundary marker | Q32: the southwesterly side of the Nagog hill road | S32: GIS iPad | T32: 42.507427 | U32: =ABS(TRUNC(T32)) -> 42 | V32: =TRUNC(ABS(T32-TRUNC(T32))*60) -> 30 | W32: =(T32 -(U32+V32/60))*60*60 -> 26.7372 | X32: -71.449538 | Y32: =ABS(TRUNC(X32)) -> 71 | Z32: =TRUNC(ABS(X32-TRUNC(X32))*60) -> 26 | AA32: =(ABS(X32) -(Y32+Z32/60))*60*60 -> 58.3368 | AB32: =IF(ISBLANK(T32),"","https://openstreetmap.org/?mlat="&T32&"&mlon="&X32&"#map=16/"&T32&"/"&X32) -> https://openstreetmap.org/?mlat=42.507427&mlon=-71.449538#map=16/42.507427/-71.449538 | AD32: 29
A33: ="Acton"&IF(C33="X","/Boxborough","")&IF(F33="X","/Carlisle","")&IF(G33="X","/Concord","")&IF(D33="X","/Littleton","")&IF(I33="X","/Maynard","")&IF(J33="X","/Stow","")&IF(H33="X","/Sudbury","")&IF(E33="X","/Westford","")&IF(ISBLANK(AC33),""," "&AC33) &IF(OR(B33="Street Crossing",B33="Witness")," "&K33,"") -> Acton/Littleton Nashoba Road | B33: Street Crossing | D33: X | K33: Nashoba Road | L33: Great Road | N33: Not Found | O33: 45810 | P33: maybe never installed because it would have been so close to the Acton/Littleton monument? | Q33: no | S33: map estimate | T33: 42.52215 | U33: =ABS(TRUNC(T33)) -> 42 | V33: =TRUNC(ABS(T33-TRUNC(T33))*60) -> 31 | W33: =(T33 -(U33+V33/60))*60*60 -> 19.74 | X33: -71.43502 | Y33: =ABS(TRUNC(X33)) -> 71 | Z33: =TRUNC(ABS(X33-TRUNC(X33))*60) -> 26 | AA33: =(ABS(X33) -(Y33+Z33/60))*60*60 -> 6.072 | AB33: =IF(ISBLANK(T33),"","https://openstreetmap.org/?mlat="&T33&"&mlon="&X33&"#map=16/"&T33&"/"&X33) -> https://openstreetmap.org/?mlat=42.52215&mlon=-71.43502#map=16/42.52215/-71.43502 | AD33: 27
A34: ="Acton"&IF(C34="X","/Boxborough","")&IF(F34="X","/Carlisle","")&IF(G34="X","/Concord","")&IF(D34="X","/Littleton","")&IF(I34="X","/Maynard","")&IF(J34="X","/Stow","")&IF(H34="X","/Sudbury","")&IF(E34="X","/Westford","")&IF(ISBLANK(AC34),""," "&AC34) &IF(OR(B34="Street Crossing",B34="Witness")," "&K34,"") -> Acton/Littleton Newtown Road | B34: Street Crossing | D34: X | K34: Newtown Road | L34: Fort Pond Hill Road | M34: between Lillian and Bulette Rd | N34: Painted | O34: 45810 | Q34: the southwesterly side of the Fort Pond road. | S34: GIS iPad | T34: 42.501417 | U34: =ABS(TRUNC(T34)) -> 42 | V34: =TRUNC(ABS(T34-TRUNC(T34))*60) -> 30 | W34: =(T34 -(U34+V34/60))*60*60 -> 5.1012 | X34: -71.469495 | Y34: =IF(ISBLANK(X34),"",ABS(TRUNC(X34))) -> 71 | Z34: =IF(ISBLANK(X34),"",TRUNC(ABS(X34-TRUNC(X34))*60)) -> 28 | AA34: =IF(ISBLANK(X34),"",(ABS(X34) -(Y34+Z34/60))*60*60) -> 10.182 | AB34: =IF(ISBLANK(T34),"","https://openstreetmap.org/?mlat="&T34&"&mlon="&X34&"#map=16/"&T34&"/"&X34) -> https://openstreetmap.org/?mlat=42.501417&mlon=-71.469495#map=16/42.501417/-71.469495 | AD34: 34
A35: ="Acton"&IF(C35="X","/Boxborough","")&IF(F35="X","/Carlisle","")&IF(G35="X","/Concord","")&IF(D35="X","/Littleton","")&IF(I35="X","/Maynard","")&IF(J35="X","/Stow","")&IF(H35="X","/Sudbury","")&IF(E35="X","/Westford","")&IF(ISBLANK(AC35),""," "&AC35) &IF(OR(B35="Street Crossing",B35="Witness")," "&K35,"") -> Acton/Littleton Sarah Indian Way | B35: Street Crossing | D35: X | K35: Sarah Indian Way | N35: Not Found | O35: 45810 | P35: Newer road. Did see stone wall town bound, but no marker. May need to find old route of road. | Q35: no | S35: map estimate | T35: 42.50527 | U35: =ABS(TRUNC(T35)) -> 42 | V35: =TRUNC(ABS(T35-TRUNC(T35))*60) -> 30 | W35: =(T35 -(U35+V35/60))*60*60 -> 18.972 | X35: -71.45672 | Y35: =IF(ISBLANK(X35),"",ABS(TRUNC(X35))) -> 71 | Z35: =IF(ISBLANK(X35),"",TRUNC(ABS(X35-TRUNC(X35))*60)) -> 27 | AA35: =IF(ISBLANK(X35),"",(ABS(X35) -(Y35+Z35/60))*60*60) -> 24.192 | AB35: =IF(ISBLANK(T35),"","https://openstreetmap.org/?mlat="&T35&"&mlon="&X35&"#map=16/"&T35&"/"&X35) -> https://openstreetmap.org/?mlat=42.50527&mlon=-71.45672#map=16/42.50527/-71.45672 | AD35: 32 | AE35: Find maps of old path of road, and look near old road crossing. Would have been added after 1904, or may be what the W B marker is pointing to.
A36: ="Acton"&IF(C36="X","/Boxborough","")&IF(F36="X","/Carlisle","")&IF(G36="X","/Concord","")&IF(D36="X","/Littleton","")&IF(I36="X","/Maynard","")&IF(J36="X","/Stow","")&IF(H36="X","/Sudbury","")&IF(E36="X","/Westford","")&IF(ISBLANK(AC36),""," "&AC36) &IF(OR(B36="Street Crossing",B36="Witness")," "&K36,"") -> Acton/Littleton W B Marker on Fort Pond Road | B36: Witness | D36: X | K36: W B Marker on Fort Pond Road | L36: Fort Pond Road | N36: Found | O36: 45810 | P36: W B Marker | Q36: no | R36: W B likely stands for Witness Bound, which were placed when a monument can't be placed at the actual location. There were no paint marks here, so we didn't paiint either. | S36: GIS iPad | T36: 42.506201 | U36: =ABS(TRUNC(T36)) -> 42 | V36: =TRUNC(ABS(T36-TRUNC(T36))*60) -> 30 | W36: =(T36 -(U36+V36/60))*60*60 -> 22.3236 | X36: -71.454125 | Y36: =IF(ISBLANK(X36),"",ABS(TRUNC(X36))) -> 71 | Z36: =IF(ISBLANK(X36),"",TRUNC(ABS(X36-TRUNC(X36))*60)) -> 27 | AA36: =IF(ISBLANK(X36),"",(ABS(X36) -(Y36+Z36/60))*60*60) -> 14.85 | AB36: =IF(ISBLANK(T36),"","https://openstreetmap.org/?mlat="&T36&"&mlon="&X36&"#map=16/"&T36&"/"&X36) -> https://openstreetmap.org/?mlat=42.506201&mlon=-71.454125#map=16/42.506201/-71.454125 | AD36: 31 | AE36: Research on what actual corner this Bound was witnessing.
A37: ="Acton"&IF(C37="X","/Boxborough","")&IF(F37="X","/Carlisle","")&IF(G37="X","/Concord","")&IF(D37="X","/Littleton","")&IF(I37="X","/Maynard","")&IF(J37="X","/Stow","")&IF(H37="X","/Sudbury","")&IF(E37="X","/Westford","")&IF(ISBLANK(AC37),""," "&AC37) &IF(OR(B37="Street Crossing",B37="Witness")," "&K37,"") -> Acton/Littleton/Westford | B37: Corner | D37: X | E37: X | K37: Westford Lane | L37: Durkee Lane | M37: Bobby's Ranch | N37: Painted | O37: Sep 24, 2025 (1) | P37: visible from the southeast corner of the fenced in area behind the main barn of Bobby's Ranch | Q37: a rough split granite monument, triangular In shape, marked A L W 1832, and situated in low woodland near an open meadow, about 800 feet northwest of a cart path leading northeasterly from Nagog pond and about 2,500 feet distant from the pond | R37: Contact owners at Bobby's Ranch before any visit. You need to walk through barn, and electricity to fence needs to be turned off. | S37: State | T37: 42.528812 | U37: =ABS(TRUNC(T37)) -> 42 | V37: =TRUNC(ABS(T37-TRUNC(T37))*60) -> 31 | W37: =(T37 -(U37+V37/60))*60*60 -> 43.723754 | X37: -71.428535 | Y37: =ABS(TRUNC(X37)) -> 71 | Z37: =TRUNC(ABS(X37-TRUNC(X37))*60) -> 25 | AA37: =(ABS(X37) -(Y37+Z37/60))*60*60 -> 42.72425 | AB37: =IF(ISBLANK(T37),"","https://openstreetmap.org/?mlat="&T37&"&mlon="&X37&"#map=16/"&T37&"/"&X37) -> https://openstreetmap.org/?mlat=42.528812154&mlon=-71.428534514#map=16/42.528812154/-71.428534514 | AD37: 24
A38: ="Acton"&IF(C38="X","/Boxborough","")&IF(F38="X","/Carlisle","")&IF(G38="X","/Concord","")&IF(D38="X","/Littleton","")&IF(I38="X","/Maynard","")&IF(J38="X","/Stow","")&IF(H38="X","/Sudbury","")&IF(E38="X","/Westford","")&IF(ISBLANK(AC38),""," "&AC38) &IF(OR(B38="Street Crossing",B38="Witness")," "&K38,"") -> Acton/Maynard Conant Street | B38: Street Crossing | I38: X | K38: Conant Street | M38: golf course | N38: Painted | O38: Jul 24, 2025 (2) | P38: mostly buried | Q38: on the northwesterly side of the Acton road, Maynard | S38: GIS iPad | T38: 42.445701 | U38: =IF(ISBLANK(T38),"",ABS(TRUNC(T38))) -> 42 | V38: =IF(ISBLANK(T38),"",TRUNC(ABS(T38-TRUNC(T38))*60)) -> 26 | W38: =IF(ISBLANK(T38),"",(T38 -(U38+V38/60))*60*60) -> 44.5236 | X38: -71.452587 | Y38: =IF(ISBLANK(X38),"",ABS(TRUNC(X38))) -> 71 | Z38: =IF(ISBLANK(X38),"",TRUNC(ABS(X38-TRUNC(X38))*60)) -> 27 | AA38: =IF(ISBLANK(X38),"",(ABS(X38) -(Y38+Z38/60))*60*60) -> 9.3132 | AB38: =IF(ISBLANK(T38),"","https://openstreetmap.org/?mlat="&T38&"&mlon="&X38&"#map=16/"&T38&"/"&X38) -> https://openstreetmap.org/?mlat=42.445701&mlon=-71.452587#map=16/42.445701/-71.452587 | AD38: 48
A39: ="Acton"&IF(C39="X","/Boxborough","")&IF(F39="X","/Carlisle","")&IF(G39="X","/Concord","")&IF(D39="X","/Littleton","")&IF(I39="X","/Maynard","")&IF(J39="X","/Stow","")&IF(H39="X","/Sudbury","")&IF(E39="X","/Westford","")&IF(ISBLANK(AC39),""," "&AC39) &IF(OR(B39="Street Crossing",B39="Witness")," "&K39,"") -> Acton/Maynard Main Street (Rte 27) | B39: Street Crossing | I39: X | K39: Main Street (Rte 27) | L39: Brown Street | M39: Christmas Motors, Bruce Freeman Rail Trail | N39: Painted | O39: Jul 24, 2025 (2) | P39: a few feet from Maynard/Acton sign (West side) | Q39: on the westerly side of the South Acton road, near its junction with the Acton road, Maynard | S39: GIS iPad | T39: 42.446230 | U39: =IF(ISBLANK(T39),"",ABS(TRUNC(T39))) -> 42 | V39: =IF(ISBLANK(T39),"",TRUNC(ABS(T39-TRUNC(T39))*60)) -> 26 | W39: =IF(ISBLANK(T39),"",(T39 -(U39+V39/60))*60*60) -> 46.428 | X39: -71.453932 | Y39: =IF(ISBLANK(X39),"",ABS(TRUNC(X39))) -> 71 | Z39: =IF(ISBLANK(X39),"",TRUNC(ABS(X39-TRUNC(X39))*60)) -> 27 | AA39: =IF(ISBLANK(X39),"",(ABS(X39) -(Y39+Z39/60))*60*60) -> 14.1552 | AB39: =IF(ISBLANK(T39),"","https://openstreetmap.org/?mlat="&T39&"&mlon="&X39&"#map=16/"&T39&"/"&X39) -> https://openstreetmap.org/?mlat=42.446230&mlon=-71.453932#map=16/42.446230/-71.453932 | AD39: 47 | AE39: Get a picture of the Maynard side of the monument.
A40: ="Acton"&IF(C40="X","/Boxborough","")&IF(F40="X","/Carlisle","")&IF(G40="X","/Concord","")&IF(D40="X","/Littleton","")&IF(I40="X","/Maynard","")&IF(J40="X","/Stow","")&IF(H40="X","/Sudbury","")&IF(E40="X","/Westford","")&IF(ISBLANK(AC40),""," "&AC40) &IF(OR(B40="Street Crossing",B40="Witness")," "&K40,"") -> Acton/Maynard Parker Street | B40: Street Crossing | I40: X | K40: Parker Street | L40: Concord Street | M40: Pine Hill Road, golf course | N40: Painted | O40: Jul 24, 2025 (2) | P40: near boundary marker on north side | Q40: on the northwesterly side of the Parmenter road | R40: partially buried | S40: GIS iPad | T40: 42.442279 | U40: =IF(ISBLANK(T40),"",ABS(TRUNC(T40))) -> 42 | V40: =IF(ISBLANK(T40),"",TRUNC(ABS(T40-TRUNC(T40))*60)) -> 26 | W40: =IF(ISBLANK(T40),"",(T40 -(U40+V40/60))*60*60) -> 32.2044 | X40: -71.443880 | Y40: =IF(ISBLANK(X40),"",ABS(TRUNC(X40))) -> 71 | Z40: =IF(ISBLANK(X40),"",TRUNC(ABS(X40-TRUNC(X40))*60)) -> 26 | AA40: =IF(ISBLANK(X40),"",(ABS(X40) -(Y40+Z40/60))*60*60) -> 37.968 | AB40: =IF(ISBLANK(T40),"","https://openstreetmap.org/?mlat="&T40&"&mlon="&X40&"#map=16/"&T40&"/"&X40) -> https://openstreetmap.org/?mlat=42.442279&mlon=-71.443880#map=16/42.442279/-71.443880 | AD40: 49 | AE40: See if Acton and Maynard want to participate in planning, funding, and implementing a repair of the buried monument.
...

Sheet Contacts
A3: First Names | B3: Last Names | C3: Affiliation | D3: Only for Town | E3: Jun 2, 2025 | F3: Jun 30, 2025 | G3: Jul 24, 2025 (1) | H3: Jul 24, 2025 (2) | I3: Jul 24, 2025 (3) | J3: Sep 16, 2025 | K3: Sep 24, 2025 (1) | L3: Sep 24, 2025 (2) | M3: Nov 6, 2025 | N3: Nov 28, 2025 | O3: Jul 18, 2026
A4: Jim | B4: Snyder-Grant | C4: Acton Select Board | E4: attended | F4: host | G4: host | H4: host | I4: host | J4: host | K4: host | L4: host | M4: attended | N4: attended | O4: attended
A5: Dean | B5: Charter | C5: Acton Select Board | E5: attended | F5: host | G5: host | H5: host | I5: host | J5: host | K5: host | L5: host | M5: attended
A6: Janet | B6: Adachi | C6: Acton Resident | E6: declined | F6: attended | G6: accepted | H6: accepted | I6: accepted | J6: declined | K6: invited
A7: Rob | B7: Gogan | C7: Acton Exchange | E7: attended | F7: invited | G7: invited | H7: invited | I7: invited | J7: invited | K7: invited
A8: Joe | B8: Cooney | C8: Acton Conservation Trust | E8: attended | F8: declined | G8: invited | H8: invited | I8: invited | J8: attended | K8: declined
A9: Andy | B9: Curran | C9: Littleton Historical Society | D9: Littleton | E9: attended | K9: attended
A10: Linda | B10: Stein | D10: Littleton | E10: attended | K10: invited
A11: Mark | B11: Rambacher | C11: Littleton Select Board | D11: Littleton | E11: attended | K11: attended
A12: Kim | B12: Kastens | C12: Acton Exchange | E12: declined | F12: declined | G12: Attended | H12: Attended | I12: Attended | J12: Declined | K12: declined
A13: Gregory | B13: Johnson | D13: Maynard | G13: invited | H13: invited | I13: invited
A14: Jeffrey | B14: Swanberg | D14: Maynard | G14: declined | H14: declined | I14: declined
A15: Mike | B15: Stevens | D15: Maynard | G15: invited | H15: invited | I15: invited
A16: Lindsay | B16: McConchie | D16: Maynard | G16: declined | H16: declined | I16: declined
A17: QinRui | B17: Pang | C17: DPW Director | D17: Sudbury | G17: attended | I17: accepted
A18: Phil | B18: Salamon | C18: Town Engineer | D18: Sudbury | G18: attended | I18: accepted
A19: JT | B19: Toole | D19: Stow | G19: declined | H19: declined | I19: declined | J19: invited
A20: Megan | B20: Birch-McMichael | D20: Stow | G20: declined | H20: declined | I20: declined | J20: invited
A21: Ingeborg Hegemann | B21: Clark | D21: Stow | G21: invited | H21: invited | I21: invited | J21: invited
A22: Hector | B22: Constanzos | D22: Stow | G22: declined | H22: declined | I22: declined | J22: invited
A23: Greg | B23: Troxel | D23: Stow | G23: attended | H23: attended | I23: attended | J23: invited
A24: various | D24: Boxborough | J24: invited
A25: various | D25: Concord | J25: declined
A26: Kristin | B26: Hilberg | D26: Boxborough | J26: attended
A27: Kristen | B27: Las | D27: Westford | K27: invited
A28: Jeremy | B28: Downs | D28: Westford | K28: invited
A29: Paul | B29: Starratt | C29: Town Engineer | D29: Westford | K29: attended
A30: Richard | B30: Perkins | C30: Land Owner | D30: Stow | I30: attended | K30: invited

Sheet KML CornersFromState
A1: Name | B1: Latitude | C1: Longitude
A2: Acton/Boxborough/Littleton | B2: 42.500186 | C2: -71.473529
A3: Acton/Boxborough/Stow | B3: 42.463784 | C3: -71.498548
A4: Acton/Carlisle 1 | B4: 42.506829 | C4: -71.391564
A5: Acton/Carlisle 2 | B5: 42.526345 | C5: -71.397947
A6: Acton/Carlisle/Concord | B6: 42.504473 | C6: -71.384947
A7: Acton/Carlisle/Westford | B7: 42.534025 | C7: -71.399515
A8: Acton/Concord/Maynard/Sudbury | B8: 42.436948 | C8: -71.430395
A9: Acton/Littleton 1 | B9: 42.522179 | C9: -71.435018
A10: Acton/Littleton 2 | B10: 42.509069 | C10: -71.44394
A11: Acton/Littleton/Westford | B11: 42.528812 | C11: -71.428535
A12: Acton/Maynard/Stow | B12: 42.450329 | C12: -71.464329
A13: Acton/Westford | B13: 42.526198 | C13: -71.423796
